# Java 尝试捕获块

> 原文:[https://www.javatpoint.com/try-catch-block](https://www.javatpoint.com/try-catch-block)

## Java 尝试块

Java **try** 块用于封装可能引发异常的代码。它必须在方法中使用。

如果 try 块中的特定语句发生异常，块代码的其余部分将不会执行。因此，建议不要将代码保存在不会引发异常的 try 块中。

Java try 块后面必须跟有 catch 或 finally 块。

### Java 试捕的语法

```

try{  
//code that may throw an exception  
}catch(Exception_class_Name ref){}  

```

### try-finally 块的语法

```

try{  
//code that may throw an exception  
}finally{}  

```

## Java 捕获块

Java catch 块用于通过在参数中声明异常类型来处理异常。声明的异常必须是父类异常(即异常)或生成的异常类型。然而，好的方法是声明生成的异常类型。

catch 块只能在 try 块之后使用。您可以使用多个 catch 块和一个 try 块。

## Java 试捕块的内部工作

![Java try-catch block](../Images/33346b8032fe42a3a33e4e91ff8b29a2.png)

JVM 首先检查异常是否被处理。如果异常未被处理，JVM 将提供一个默认的异常处理程序来执行以下任务:

*   打印出异常描述。
*   打印堆栈跟踪(发生异常的方法层次结构)。
*   导致程序终止。

但是，如果应用程序程序员处理了异常，应用程序的正常流程就会得到维护，也就是说，其余的代码都会被执行。

## 无异常处理的问题

如果不使用 try-catch 块，让我们试着理解这个问题。

### 例 1

**TryCatchExample1.java**

```

public class TryCatchExample1 {

	public static void main(String[] args) {

		int data=50/0; //may throw exception 

		System.out.println("rest of the code");

	}

}

```

[Test it Now](https://www.javatpoint.com/opr/test.jsp?filename=TryCatchExample1)

**输出:**

```
Exception in thread "main" java.lang.ArithmeticException: / by zero

```

如上例所示，不执行代码的**剩余部分(在这种情况下，不打印代码**语句的**剩余部分)。**

异常后可能有 100 行代码。如果异常没有被处理，那么异常下面的所有代码都不会被执行。

## 异常处理解决方案

让我们通过一个 java try-catch 块来看看上述问题的解决方案。

### 例 2

**TryCatchExample2.java**

```

public class TryCatchExample2 {

	public static void main(String[] args) {
		try
		{
		int data=50/0; //may throw exception 
		}
            //handling the exception
		catch(ArithmeticException e)
		{
			System.out.println(e);
		}
		System.out.println("rest of the code");
	}

}

```

[Test it Now](https://www.javatpoint.com/opr/test.jsp?filename=TryCatchExample2)

**输出:**

```
java.lang.ArithmeticException: / by zero
rest of the code

```

如上例所示，执行代码的**剩余部分，即打印代码**语句的**剩余部分。**

### 例 3

在这个例子中，我们还将代码保存在一个不会引发异常的 try 块中。

**TryCatchExample3.java**

```

public class TryCatchExample3 {

	public static void main(String[] args) {
		try
		{
		int data=50/0; //may throw exception 
                         // if exception occurs, the remaining statement will not exceute
		System.out.println("rest of the code");
		}
             // handling the exception 
		catch(ArithmeticException e)
		{
			System.out.println(e);
		}

	}

}

```

[Test it Now](https://www.javatpoint.com/opr/test.jsp?filename=TryCatchExample3)

**输出:**

```
java.lang.ArithmeticException: / by zero

```

在这里，我们可以看到，如果 try 块中出现异常，块代码的其余部分将不会执行。

### 例 4

这里，我们使用父类异常来处理异常。

**TryCatchExample4.java**

```

public class TryCatchExample4 {

	public static void main(String[] args) {
		try
		{
		int data=50/0; //may throw exception 
		}
            // handling the exception by using Exception class    
		catch(Exception e)
		{
			System.out.println(e);
		}
		System.out.println("rest of the code");
	}

}

```

[Test it Now](https://www.javatpoint.com/opr/test.jsp?filename=TryCatchExample4)

**输出:**

```
java.lang.ArithmeticException: / by zero
rest of the code

```

### 例 5

让我们看一个在异常时打印自定义消息的例子。

**TryCatchExample5.java**

```

public class TryCatchExample5 {

	public static void main(String[] args) {
		try
		{
		int data=50/0; //may throw exception 
		}
             // handling the exception
		catch(Exception e)
		{
                  // displaying the custom message
			System.out.println("Can't divided by zero");
		}
	}

}

```

[Test it Now](https://www.javatpoint.com/opr/test.jsp?filename=TryCatchExample5)

**输出:**

```
Can't divided by zero

```

### 例 6

让我们看一个在 catch 块中解决异常的例子。

**TryCatchExample6.java**

```

public class TryCatchExample6 {

	public static void main(String[] args) {
		int i=50;
		int j=0;
		int data;
		try
		{
		data=i/j; //may throw exception 
		}
            // handling the exception
		catch(Exception e)
		{
             // resolving the exception in catch block
			System.out.println(i/(j+2));
		}
	}
}

```

[Test it Now](https://www.javatpoint.com/opr/test.jsp?filename=TryCatchExample6)

**输出:**

```
25

```

### 例 7

在这个例子中，除了 try 块，我们还将异常代码包含在 catch 块中。

**TryCatchExample7.java**

```

public class TryCatchExample7 {

	public static void main(String[] args) {

		try
		{
		int data1=50/0; //may throw exception 

		}
             // handling the exception
		catch(Exception e)
		{
            // generating the exception in catch block
		int data2=50/0; //may throw exception 

		}
	System.out.println("rest of the code");
	}
}

```

[Test it Now](https://www.javatpoint.com/opr/test.jsp?filename=TryCatchExample7)

**输出:**

```
Exception in thread "main" java.lang.ArithmeticException: / by zero

```

在这里，我们可以看到 catch 块不包含异常代码。因此，将异常代码包含在 try 块中，并仅使用 catch 块来处理异常。

### 例 8

在这个例子中，我们用不同类型的异常类(ArrayIndexOutOfBoundsException)来处理生成的异常(算术异常)。

**TryCatchExample8.java**

```

public class TryCatchExample8 {

	public static void main(String[] args) {
		try
		{
		int data=50/0; //may throw exception 

		}
            // try to handle the ArithmeticException using ArrayIndexOutOfBoundsException
		catch(ArrayIndexOutOfBoundsException e)
		{
			System.out.println(e);
		}
		System.out.println("rest of the code");
	}

}

```

[Test it Now](https://www.javatpoint.com/opr/test.jsp?filename=TryCatchExample8)

**输出:**

```
Exception in thread "main" java.lang.ArithmeticException: / by zero

```

### 例 9

让我们看一个处理另一个未检查异常的例子。

**TryCatchExample9.java**

```

public class TryCatchExample9 {

	public static void main(String[] args) {
		try
		{
		int arr[]= {1,3,5,7};
		System.out.println(arr[10]); //may throw exception 
		}
            // handling the array exception
		catch(ArrayIndexOutOfBoundsException e)
		{
			System.out.println(e);
		}
		System.out.println("rest of the code");
	}

}

```

[Test it Now](https://www.javatpoint.com/opr/test.jsp?filename=TryCatchExample9)

**输出:**

```
java.lang.ArrayIndexOutOfBoundsException: 10
rest of the code

```

### 例 10

让我们看一个处理检查异常的例子。

**TryCatchExample10.java**

```

import java.io.FileNotFoundException;
import java.io.PrintWriter;

public class TryCatchExample10 {

	public static void main(String[] args) {

		PrintWriter pw;
		try {
			pw = new PrintWriter("jtp.txt"); //may throw exception 
			pw.println("saved");
		}
// providing the checked exception handler
 catch (FileNotFoundException e) {

			System.out.println(e);
		}		
	System.out.println("File saved successfully");
	}
}

```

[Test it Now](https://www.javatpoint.com/opr/test.jsp?filename=TryCatchExample10)

**输出:**

```
File saved successfully

```

* * *