# Java 嵌套`try`块

> 原文：<https://www.javatpoint.com/nested-try-block>

在 Java 中，允许在另一个`try`块中使用一个`try`块。它被称为嵌套的 `try`块。我们在 `try`块中输入语句的每个语句，该异常的上下文都被推送到堆栈上。

比如**内试块**可以处理**arrayindeoutofboundsexception**，而**外试块**可以处理**算术异常**(除零)。

### 为什么使用嵌套的 `try`块

有时可能会出现这样的情况，块的一部分可能导致一个错误，而整个块本身可能导致另一个错误。在这种情况下，异常处理器必须嵌套。

### 语法:

```java

....  
//main try block
try  
{  
    statement 1;  
    statement 2;  
//try catch block within another try block
    try  
    {  
        statement 3;  
        statement 4;  
//try catch block within nested try block
    	try  
    	{  
        	statement 5;  
        	statement 6;  
   	 }  
    	catch(Exception e2)  
    	{  
//exception message
    	}  

    }  
    catch(Exception e1)  
    {  
//exception message
    }  
}  
//catch block of parent (outer) try block
catch(Exception e3)  
{  
//exception message
}  
.... 

```

## Java 嵌套尝试示例

### 例 1

让我们看一个例子，其中我们针对两个不同的异常将一个 `try`块放在另一个 `try`块中。

在 nesedtryblock . Java 中

```java

public class NestedTryBlock{  
 public static void main(String args[]){ 
 //outer try block 
  try{  
  //inner try block 1
    try{  
     System.out.println("going to divide by 0");  
     int b =39/0;  
   }
    //catch block of inner try block 1
    catch(ArithmeticException e)
    {
      System.out.println(e);
    }  

    //inner try block 2
    try{  
    int a[]=new int[5];  

    //assigning the value out of array bounds
     a[5]=4;  
     }

    //catch block of inner try block 2
    catch(ArrayIndexOutOfBoundsException e)
    {
       System.out.println(e);
    }  

    System.out.println("other statement");  
  }
  //catch block of outer try block
  catch(Exception e)
  {
    System.out.println("handled the exception (outer catch)");
  }  

  System.out.println("normal flow..");  
 }  
}

```

**输出:**

![Java Nested try block](../img/f12eb2ede3a24e4be21cda95b2af6684.png)

当任何 `try`块没有特定异常的 `catch`块时，将检查外部(父)`try`块的 `catch`块是否有该异常，如果匹配，将执行外部 `try`块的 `catch`块。

如果代码中指定的 `catch`块都不能处理该异常，那么 Java 运行时系统将处理该异常。然后显示系统为该异常生成的消息。

### 例 2

让我们考虑下面的例子。这里嵌套的 `try`块(内部 `try`块 2)中的 `try`块不处理异常。然后，该控件被转移到其父`try`块(内部`try`块 1)。如果它不处理异常，那么控制被转移到主 `try`块(外部 `try`块)，在那里适当的 `catch`块处理异常。这被称为筑巢。

在 nesedtryblock . Java 中

```java

public class NestedTryBlock2 {

    public static void main(String args[])
    {
        // outer (main) try block
        try {

            //inner try block 1 
            try {

                // inner try block 2
                try {
                    int arr[] = { 1, 2, 3, 4 };

                    //printing the array element out of its bounds
                    System.out.println(arr[10]);
                }

                // to handles ArithmeticException
                catch (ArithmeticException e) {
                    System.out.println("Arithmetic exception");
                    System.out.println(" inner try block 2");
                }
            }

            // to handle ArithmeticException 
            catch (ArithmeticException e) {
                System.out.println("Arithmetic exception");
                System.out.println("inner try block 1");
            }
        }

        // to handle ArrayIndexOutOfBoundsException 
        catch (ArrayIndexOutOfBoundsException e4) {
            System.out.print(e4);
            System.out.println(" outer (main) try block");
        }
        catch (Exception e5) {
            System.out.print("Exception");
            System.out.println(" handled in main try-block");
        }
    }
}

```

**输出:**

![Java Nested try block](../img/755d74339f5813ec30d9a854447ae91e.png)

* * *