# Java 最终块

> 原文：<https://www.javatpoint.com/finally-block-in-exception-handling>

**Java finally block** 是用于执行关闭连接等重要代码的块。

无论是否处理异常，总是执行 Java finally 块。因此，它包含所有需要打印的必要语句，无论异常是否发生。

最后一个块跟在 try-catch 块后面。

### 最后块的流程图

![Java finally block](../img/41f03ddeb31de0e267f1d4fff5505ed0.png)

#### 注意:如果不处理异常，在终止程序之前，JVM 会执行最后一个块(如果有的话)。

## 为什么用 Java 最后块？

*   最后块在 Java 中可以用来放“**清理**”代码比如关闭一个文件，关闭连接等。
*   要打印的重要报表可以放在 finally 块中。

## Java 的用法

让我们看看可以使用 Java finally block 的不同情况。

### 情况 1:当异常没有发生时

让我们看看下面的例子，其中 Java 程序没有抛出任何异常，finally 块在 try 块之后执行。

**TestFinallyBlock.java**

```

class TestFinallyBlock {  
  public static void main(String args[]){  
  try{  
//below code do not throw any exception
   int data=25/5;  
   System.out.println(data);  
  }  
//catch won't be executed
  catch(NullPointerException e){
System.out.println(e);
}  
//executed regardless of exception occurred or not
 finally {
System.out.println("finally block is always executed");
}  

System.out.println("rest of phe code...");  
  }  
}  

```

**输出:**

![Java finally block](../img/ad65691ccae137ab6693a0fdd5442513.png)

### 情况 2:当异常发生但不由 catch 块处理时

让我们看看填充的例子。这里，代码抛出一个异常，但是 catch 块无法处理它。尽管如此，finally 块在 try 块之后执行，然后程序异常终止。

**TestFinallyBlock1.java**

```

public class TestFinallyBlock1{  
	  public static void main(String args[]){ 

	  try {  

	  	System.out.println("Inside the try block");

	  	//below code throws divide by zero exception
	   int data=25/0;  
	   System.out.println(data);  
	  }  
	  //cannot handle Arithmetic type exception
	  //can only accept Null Pointer type exception
	  catch(NullPointerException e){
	  	System.out.println(e);
	  } 

	  //executes regardless of exception occured or not 
	  finally {
	  	System.out.println("finally block is always executed");
	  }  

	  System.out.println("rest of the code...");  
	  }  
	}  

```

**输出:**

![Java finally block](../img/00865b10ce887414210d986dda01dfa1.png)

### 情况 3:当异常发生并由 catch 块处理时

**示例:**

让我们看看下面的例子，其中 Java 代码抛出一个异常，catch 块处理该异常。稍后，在 try-catch 块之后执行 finally 块。此外，其余代码也正常执行。

**TestFinallyBlock2.java**

```

public class TestFinallyBlock2{  
	  public static void main(String args[]){ 

	  try {  

	  	System.out.println("Inside try block");

	  	//below code throws divide by zero exception
	   int data=25/0;  
	   System.out.println(data);  
	  } 

	  //handles the Arithmetic Exception / Divide by zero exception
	  catch(ArithmeticException e){
	  	System.out.println("Exception handled");
	  	System.out.println(e);
	  } 

	  //executes regardless of exception occured or not 
	  finally {
	  	System.out.println("finally block is always executed");
	  }  

	  System.out.println("rest of the code...");  
	  }  
	}

```

**输出:**

![Java finally block](../img/fd67eb940e14187ae092d7c493413475.png)

#### 规则:对于每个尝试块，可以有零个或多个捕获块，但只能有一个最终块。

#### 注意:如果程序退出(通过调用 System.exit()或通过导致导致进程中止的致命错误)，将不会执行 finally 块。

* * *