# Java 抛出异常

> 原文：<https://www.javatpoint.com/throw-keyword>

在 Java 中，异常允许我们编写高质量的代码，在编译时而不是运行时检查错误，我们可以创建自定义异常，使代码恢复和调试更容易。

## Java throw 关键字

Java throw 关键字用于显式抛出异常。

我们指定要抛出的**异常**对象。异常包含一些提供错误描述的消息。这些异常可能与用户输入、服务器等有关。

我们可以通过 throw 关键字在 Java 中抛出选中或未选中的异常。主要用于抛出自定义异常。我们将在本节后面讨论自定义异常。

我们还可以定义自己的一组条件，并使用 throw 关键字显式抛出异常。例如，如果我们用一个数除以另一个数，我们可以抛出 ArithmeticException。在这里，我们只需要设置条件并使用 throw 关键字抛出异常。

下面给出了 Java throw 关键字的语法。

抛出实例，即，

```

throw new exception_class("error message");

```

让我们看看抛出 IOException 的例子。

```

throw new IOException("sorry device error"); 

```

其中实例必须是可抛出类型或可抛出子类。例如，异常是可抛出的子类，用户定义的异常通常扩展异常类。

## Java 抛出关键字示例

### 示例 1:引发未检查的异常

在本例中，我们创建了一个名为 validate()的方法，该方法接受一个整数作为参数。如果年龄小于 18 岁，我们抛出算术异常，否则打印消息欢迎投票。

**TestThrow1.java**

在本例中，我们创建了将整数值作为参数的 validate 方法。如果年龄小于 18 岁，我们抛出算术异常，否则打印消息欢迎投票。

```

public class TestThrow1 { 
	//function to check if person is eligible to vote or not 
	public static void validate(int age) {
		if(age<18) {
			//throw Arithmetic exception if not eligible to vote
			throw new ArithmeticException("Person is not eligible to vote");  
		}
		else {
			System.out.println("Person is eligible to vote!!");
		}
	}
	//main method
	public static void main(String args[]){
		//calling the function
		validate(13);
		System.out.println("rest of the code...");  
  }  
}  

```

**输出:**

![Java throw keyword](../img/26c4e8a915255cb475a8f460aa4893e4.png)

上面的代码抛出了一个未检查的异常。同样，我们也可以抛出未检查的和用户定义的异常。

#### 注意:如果我们从一个方法中抛出未检查的异常，那么必须处理该异常或者在 throws 子句中声明。

如果我们使用 throw 关键字抛出一个选中的异常，那么必须使用 catch 块来处理该异常，或者方法必须使用 throws 声明来声明它。

### 示例 2:引发选中的异常

#### 注意:Error 和 RuntimeException 的每个子类在 Java 中都是未检查的异常。选中的异常是 Throwable 类下的所有其他异常。

**TestThrow2.java**

```

import java.io.*;

public class TestThrow2 { 

	//function to check if person is eligible to vote or not 
	public static void method() throws FileNotFoundException {

		FileReader file = new FileReader("C:\\Users\\Anurati\\Desktop\\abc.txt");
		BufferedReader fileInput = new BufferedReader(file);

		throw new FileNotFoundException();

	}
	//main method
	public static void main(String args[]){
		try
        {
            method();
        } 
        catch (FileNotFoundException e) 
        {
            e.printStackTrace();
        }
		System.out.println("rest of the code...");  
  }  
}  

```

**输出:**

![Java throw keyword](../img/92aa8d1a13e9a1bcfec0a637779f76ac.png)

### 示例 3:引发用户定义的异常

exception is everything else under the Throwable class.

**TestThrow3.java**

```

// class represents user-defined exception
class UserDefinedException extends Exception
{
    public UserDefinedException(String str)
    {
        // Calling constructor of parent Exception
        super(str);
    }
}
// Class that uses above MyException
public class TestThrow3
{
    public static void main(String args[])
    {
        try
        {
            // throw an object of user defined exception
            throw new UserDefinedException("This is user-defined exception");
        }
        catch (UserDefinedException ude)
        {
            System.out.println("Caught the exception");
            // Print the message from MyException object
            System.out.println(ude.getMessage());
        }
    }
} 

```

**输出:**

![Java throw keyword](../img/a17dde783f1586e5e630585b51dfcf49.png)

* * *