# Java `throws`关键字

> 原文：<https://www.javatpoint.com/throws-keyword-and-difference-between-throw-and-throws>

**Java `throws`关键字**用于声明异常。它向程序员提供了可能发生异常的信息。所以，程序员最好提供异常处理代码，这样可以保持程序的正常流程。

异常处理主要用于处理被检查的异常。如果出现任何未检查的异常，如 NullPointerException，这是程序员的错，因为他没有在使用代码之前检查代码。

### Java 抛出的语法

```java

return_type method_name() throws exception_class_name{
//method code
}

```

### 应该声明哪个异常？

**Ans:** 仅选中异常，因为:

*   **未检查的异常:**在我们的控制之下，因此我们可以更正代码。
*   **错误:**超出我们的控制。例如，如果发生 VirtualMachineError 或 StackOverflowError，我们将无法执行任何操作。

### Java `throws`关键字的优势

现在可以传播已检查的异常(在调用栈中转发)。

它向方法的调用方提供关于异常的信息。

## Java 抛出示例

让我们看看 Java throws 子句的例子，它描述了被检查的异常可以通过 throws 关键字传播。

**Testthrows1.java**

```java

import java.io.IOException;
class Testthrows1{
  void m()throws IOException{
    throw new IOException("device error");//checked exception
  }
  void n()throws IOException{
    m();
  }
  void p(){
   try{
    n();
   }catch(Exception e){System.out.println("exception handled");}
  }
  public static void main(String args[]){
   Testthrows1 obj=new Testthrows1();
   obj.p();
   System.out.println("normal flow...");
  }
}

```

[Test it Now](https://www.javatpoint.com/opr/test.jsp?filename=Testthrows1)

**输出:**

```java
exception handled
normal flow...

```

#### 规则:如果我们正在调用一个声明异常的方法，我们必须要么捕获异常，要么声明异常。

**有两种情况:**

1.  **案例 1:** 我们已经捕获了异常，即我们已经使用 try/`catch`块处理了异常。
2.  **情况 2:** 我们已经声明了异常，即使用方法指定了 throws 关键字。

### 案例 1:使用 try-`catch`块处理异常

在我们处理异常的情况下，无论异常是否在程序中发生，代码都会被很好地执行。

**Testthrows2.java**

```java

import java.io.*;
class M{
 void method()throws IOException{
  throw new IOException("device error");
 }
}
public class Testthrows2{
   public static void main(String args[]){
    try{
     M m=new M();
     m.method();
    }catch(Exception e){System.out.println("exception handled");}   

    System.out.println("normal flow...");
  }
}

```

[Test it Now](https://www.javatpoint.com/opr/test.jsp?filename=Testthrows2)

**输出:**

```java
exception handled
       normal flow...

```

### 案例 2:声明异常

*   在我们声明异常的情况下，如果异常没有发生，代码将被很好地执行。
*   万一我们声明了异常，异常发生了，就会在运行时抛出，因为**抛出的**不处理异常。

让我们看看这两个场景的例子。

***A)如果没有发生异常***

**Testthrows3.java**

```java

import java.io.*;
class M{
 void method()throws IOException{
  System.out.println("device operation performed");
 }
}
class Testthrows3{
   public static void main(String args[])throws IOException{//declare exception
     M m=new M();
     m.method();

    System.out.println("normal flow...");
  }
}

```

[Test it Now](https://www.javatpoint.com/opr/test.jsp?filename=Testthrows3)

**输出:**

```java
device operation performed
       normal flow...

```

***B)如果发生异常***

**Testthrows4.java**

```java

import java.io.*;
class M{
 void method()throws IOException{
  throw new IOException("device error");
 }
}
class Testthrows4{
   public static void main(String args[])throws IOException{//declare exception
     M m=new M();
     m.method();

    System.out.println("normal flow...");
  }
}

```

[Test it Now](https://www.javatpoint.com/opr/test.jsp?filename=Testthrows4)

**输出:**

![Java throw keyword](../img/32d5177002eb8a9aceecc2662fa159e1.png)

* * *

### 投掷和投掷的区别

[Click me for details](difference-between-throw-and-throws-in-java)

### 我们可以重新提出一个例外吗？

是的，通过在 `catch`块中抛出相同的异常。

* * *